.package create: /workdir/kazoo-2.9.0/.tox/.package
.package installdeps: setuptools >= 46.4.0, wheel
/workdir/kazoo-2.9.0/.tox/.package/lib/python3.10/site-packages/setuptools/config/setupcfg.py:463: SetuptoolsDeprecationWarning: The license_file parameter is deprecated, use license_files instead.
  warnings.warn(msg, warning_class)
warning: no previously-included files matching '*pyc' found anywhere in distribution
warning: no previously-included files matching '*pyo' found anywhere in distribution
warning: no previously-included files matching '__pycache__' found anywhere in distribution
warning: no previously-included files found matching '.gitignore'
warning: no previously-included files found matching '.travis.yml.bak'
warning: no previously-included files found matching '.clog.toml'
no previously-included directories found matching '.github'
warning: no previously-included files found matching 'Makefile'
warning: no previously-included files found matching 'run_failure.py'
/workdir/kazoo-2.9.0/.tox/.package/lib/python3.10/site-packages/setuptools/config/setupcfg.py:463: SetuptoolsDeprecationWarning: The license_file parameter is deprecated, use license_files instead.
  warnings.warn(msg, warning_class)
warning: no previously-included files matching '*pyc' found anywhere in distribution
warning: no previously-included files matching '*pyo' found anywhere in distribution
warning: no previously-included files matching '__pycache__' found anywhere in distribution
warning: no previously-included files found matching '.gitignore'
warning: no previously-included files found matching '.travis.yml.bak'
warning: no previously-included files found matching '.clog.toml'
no previously-included directories found matching '.github'
warning: no previously-included files found matching 'Makefile'
warning: no previously-included files found matching 'run_failure.py'
cpythonlibtest-unit-test-tests create: /workdir/kazoo-2.9.0/.tox/cpythonlibtest-unit-test-tests
cpythonlibtest-unit-test-tests installdeps: mock, pytest
cpythonlibtest-unit-test-tests inst: /workdir/kazoo-2.9.0/.tox/.tmp/package/1/kazoo-2.9.0.dev0.tar.gz
cpythonlibtest-unit-test-tests installed: exceptiongroup==1.2.0,iniconfig==2.0.0,kazoo @ file:///workdir/kazoo-2.9.0/.tox/.tmp/package/1/kazoo-2.9.0.dev0.tar.gz#sha256=afe235a0ac1e3be3e8387583f8bb4b233ac39ccd0116ca56bb91fc4106994a38,mock==5.1.0,packaging==23.2,pluggy==1.3.0,pytest==7.4.3,six==1.16.0,tomli==2.0.1
cpythonlibtest-unit-test-tests run-test-pre: PYTHONHASHSEED='2319097616'
cpythonlibtest-unit-test-tests run-test: commands[0] | pytest -v --tb=native --junitxml /workdir/results/kazoo/2.9.0/1/cpython-test-results.xml
============================= test session starts ==============================
platform linux -- Python 3.10.8, pytest-7.4.3, pluggy-1.3.0 -- /workdir/kazoo-2.9.0/.tox/cpythonlibtest-unit-test-tests/bin/python
cachedir: .tox/cpythonlibtest-unit-test-tests/.pytest_cache
rootdir: /workdir/kazoo-2.9.0
configfile: setup.cfg
collecting ... collected 20 items
INTERNALERROR> Traceback (most recent call last):
INTERNALERROR>   File "/workdir/kazoo-2.9.0/.tox/cpythonlibtest-unit-test-tests/lib/python3.10/site-packages/_pytest/main.py", line 271, in wrap_session
INTERNALERROR>     session.exitstatus = doit(config, session) or 0
INTERNALERROR>   File "/workdir/kazoo-2.9.0/.tox/cpythonlibtest-unit-test-tests/lib/python3.10/site-packages/_pytest/main.py", line 324, in _main
INTERNALERROR>     config.hook.pytest_collection(session=session)
INTERNALERROR>   File "/workdir/kazoo-2.9.0/.tox/cpythonlibtest-unit-test-tests/lib/python3.10/site-packages/pluggy/_hooks.py", line 493, in __call__
INTERNALERROR>     return self._hookexec(self.name, self._hookimpls, kwargs, firstresult)
INTERNALERROR>   File "/workdir/kazoo-2.9.0/.tox/cpythonlibtest-unit-test-tests/lib/python3.10/site-packages/pluggy/_manager.py", line 115, in _hookexec
INTERNALERROR>     return self._inner_hookexec(hook_name, methods, kwargs, firstresult)
INTERNALERROR>   File "/workdir/kazoo-2.9.0/.tox/cpythonlibtest-unit-test-tests/lib/python3.10/site-packages/pluggy/_callers.py", line 152, in _multicall
INTERNALERROR>     return outcome.get_result()
INTERNALERROR>   File "/workdir/kazoo-2.9.0/.tox/cpythonlibtest-unit-test-tests/lib/python3.10/site-packages/pluggy/_result.py", line 114, in get_result
INTERNALERROR>     raise exc.with_traceback(exc.__traceback__)
INTERNALERROR>   File "/workdir/kazoo-2.9.0/.tox/cpythonlibtest-unit-test-tests/lib/python3.10/site-packages/pluggy/_callers.py", line 77, in _multicall
INTERNALERROR>     res = hook_impl.function(*args)
INTERNALERROR>   File "/workdir/kazoo-2.9.0/.tox/cpythonlibtest-unit-test-tests/lib/python3.10/site-packages/_pytest/main.py", line 335, in pytest_collection
INTERNALERROR>     session.perform_collect()
INTERNALERROR>   File "/workdir/kazoo-2.9.0/.tox/cpythonlibtest-unit-test-tests/lib/python3.10/site-packages/_pytest/main.py", line 675, in perform_collect
INTERNALERROR>     self.items.extend(self.genitems(node))
INTERNALERROR>   File "/workdir/kazoo-2.9.0/.tox/cpythonlibtest-unit-test-tests/lib/python3.10/site-packages/_pytest/main.py", line 845, in genitems
INTERNALERROR>     yield from self.genitems(subnode)
INTERNALERROR>   File "/workdir/kazoo-2.9.0/.tox/cpythonlibtest-unit-test-tests/lib/python3.10/site-packages/_pytest/main.py", line 842, in genitems
INTERNALERROR>     rep = collect_one_node(node)
INTERNALERROR>   File "/workdir/kazoo-2.9.0/.tox/cpythonlibtest-unit-test-tests/lib/python3.10/site-packages/_pytest/runner.py", line 550, in collect_one_node
INTERNALERROR>     ihook.pytest_exception_interact(node=collector, call=call, report=rep)
INTERNALERROR>   File "/workdir/kazoo-2.9.0/.tox/cpythonlibtest-unit-test-tests/lib/python3.10/site-packages/pluggy/_hooks.py", line 493, in __call__
INTERNALERROR>     return self._hookexec(self.name, self._hookimpls, kwargs, firstresult)
INTERNALERROR>   File "/workdir/kazoo-2.9.0/.tox/cpythonlibtest-unit-test-tests/lib/python3.10/site-packages/pluggy/_manager.py", line 115, in _hookexec
INTERNALERROR>     return self._inner_hookexec(hook_name, methods, kwargs, firstresult)
INTERNALERROR>   File "/workdir/kazoo-2.9.0/.tox/cpythonlibtest-unit-test-tests/lib/python3.10/site-packages/pluggy/_callers.py", line 113, in _multicall
INTERNALERROR>     raise exception.with_traceback(exception.__traceback__)
INTERNALERROR>   File "/workdir/kazoo-2.9.0/.tox/cpythonlibtest-unit-test-tests/lib/python3.10/site-packages/pluggy/_callers.py", line 77, in _multicall
INTERNALERROR>     res = hook_impl.function(*args)
INTERNALERROR>   File "/workdir/kazoo-2.9.0/kazoo/tests/conftest.py", line 7, in pytest_exception_interact
INTERNALERROR>     cluster = node._testcase.cluster
INTERNALERROR> AttributeError: 'Module' object has no attribute '_testcase'

============================ no tests ran in 0.27s =============================
ERROR: InvocationError for command /workdir/kazoo-2.9.0/.tox/cpythonlibtest-unit-test-tests/bin/pytest -v --tb=native --junitxml /workdir/results/kazoo/2.9.0/1/cpython-test-results.xml (exited with code 3)
___________________________________ summary ____________________________________
ERROR:   cpythonlibtest-unit-test-tests: commands failed
