GLOB sdist-make: /workdir/oci-2.104.3/setup.py
cpythonlibtest-unit-test-tests create: /workdir/oci-2.104.3/.tox/cpythonlibtest-unit-test-tests
cpythonlibtest-unit-test-tests installdeps: mock, pytest, -rrequirements.txt
cpythonlibtest-unit-test-tests inst: /workdir/oci-2.104.3/.tox/.tmp/package/1/oci-2.104.3.zip
cpythonlibtest-unit-test-tests installed: alabaster==0.7.13,atomicwrites==1.4.1,attrs==19.1.0,autodocsumm==0.1.11,Babel==2.13.1,certifi==2023.11.17,cffi==1.16.0,charset-normalizer==3.3.2,circuitbreaker==1.4.0,coverage==4.5.2,cryptography==39.0.2,docutils==0.17.1,filelock==3.13.1,flake8==5.0.4,idna==3.4,imagesize==1.4.1,Jinja2==3.0.3,MarkupSafe==2.1.3,mccabe==0.7.0,mock==2.0.0,more-itertools==10.1.0,multidict==6.0.4,oci @ file:///workdir/oci-2.104.3/.tox/.tmp/package/1/oci-2.104.3.zip#sha256=658333ae48cd81b908608fa512cc7f976d45925efc5b9c986a7536fea4895bee,packaging==23.2,pbr==6.0.0,pluggy==0.13.1,py==1.11.0,pycodestyle==2.9.1,pycparser==2.21,pyflakes==2.5.0,Pygments==2.17.2,pyOpenSSL==23.2.0,pytest==4.1.0,pytest-cov==2.6.1,python-dateutil==2.7.3,pytz==2023.3.post1,PyYAML==6.0.1,requests==2.31.0,six==1.16.0,snowballstemmer==2.2.0,Sphinx==1.8.3,sphinx-rtd-theme==0.4.2,sphinxcontrib-serializinghtml==1.1.5,sphinxcontrib-websupport==1.2.4,toml==0.10.2,tox==3.14.3,urllib3==2.1.0,vcrpy==2.0.1,virtualenv==16.7.9,wrapt==1.16.0,yarl==1.9.3
cpythonlibtest-unit-test-tests run-test-pre: PYTHONHASHSEED='862372309'
cpythonlibtest-unit-test-tests run-test: commands[0] | pytest -v --tb=native --junitxml /workdir/results/oci/2.104.3/1/cpython-test-results.xml
Traceback (most recent call last):
  File "<frozen importlib._bootstrap>", line 939, in _find_spec
AttributeError: 'AssertionRewritingHook' object has no attribute 'find_spec'

During handling of the above exception, another exception occurred:

Traceback (most recent call last):
  File "/workdir/oci-2.104.3/.tox/cpythonlibtest-unit-test-tests/bin/pytest", line 8, in <module>
    sys.exit(main())
  File "/workdir/oci-2.104.3/.tox/cpythonlibtest-unit-test-tests/lib/python3.10/site-packages/_pytest/config/__init__.py", line 61, in main
    config = _prepareconfig(args, plugins)
  File "/workdir/oci-2.104.3/.tox/cpythonlibtest-unit-test-tests/lib/python3.10/site-packages/_pytest/config/__init__.py", line 195, in _prepareconfig
    return pluginmanager.hook.pytest_cmdline_parse(
  File "/workdir/oci-2.104.3/.tox/cpythonlibtest-unit-test-tests/lib/python3.10/site-packages/pluggy/hooks.py", line 286, in __call__
    return self._hookexec(self, self.get_hookimpls(), kwargs)
  File "/workdir/oci-2.104.3/.tox/cpythonlibtest-unit-test-tests/lib/python3.10/site-packages/pluggy/manager.py", line 93, in _hookexec
    return self._inner_hookexec(hook, methods, kwargs)
  File "/workdir/oci-2.104.3/.tox/cpythonlibtest-unit-test-tests/lib/python3.10/site-packages/pluggy/manager.py", line 84, in <lambda>
    self._inner_hookexec = lambda hook, methods, kwargs: hook.multicall(
  File "/workdir/oci-2.104.3/.tox/cpythonlibtest-unit-test-tests/lib/python3.10/site-packages/pluggy/callers.py", line 203, in _multicall
    gen.send(outcome)
  File "/workdir/oci-2.104.3/.tox/cpythonlibtest-unit-test-tests/lib/python3.10/site-packages/_pytest/helpconfig.py", line 93, in pytest_cmdline_parse
    config = outcome.get_result()
  File "/workdir/oci-2.104.3/.tox/cpythonlibtest-unit-test-tests/lib/python3.10/site-packages/pluggy/callers.py", line 80, in get_result
    raise ex[1].with_traceback(ex[2])
  File "/workdir/oci-2.104.3/.tox/cpythonlibtest-unit-test-tests/lib/python3.10/site-packages/pluggy/callers.py", line 187, in _multicall
    res = hook_impl.function(*args)
  File "/workdir/oci-2.104.3/.tox/cpythonlibtest-unit-test-tests/lib/python3.10/site-packages/_pytest/config/__init__.py", line 652, in pytest_cmdline_parse
    self.parse(args)
  File "/workdir/oci-2.104.3/.tox/cpythonlibtest-unit-test-tests/lib/python3.10/site-packages/_pytest/config/__init__.py", line 838, in parse
    self._preparse(args, addopts=addopts)
  File "/workdir/oci-2.104.3/.tox/cpythonlibtest-unit-test-tests/lib/python3.10/site-packages/_pytest/config/__init__.py", line 784, in _preparse
    self.pluginmanager.load_setuptools_entrypoints("pytest11")
  File "/workdir/oci-2.104.3/.tox/cpythonlibtest-unit-test-tests/lib/python3.10/site-packages/pluggy/manager.py", line 299, in load_setuptools_entrypoints
    plugin = ep.load()
  File "/usr/local/lib/python3.10/importlib/metadata/__init__.py", line 171, in load
    module = import_module(match.group('module'))
  File "/usr/local/lib/python3.10/importlib/__init__.py", line 126, in import_module
    return _bootstrap._gcd_import(name[level:], package, level)
  File "<frozen importlib._bootstrap>", line 1050, in _gcd_import
  File "<frozen importlib._bootstrap>", line 1027, in _find_and_load
  File "<frozen importlib._bootstrap>", line 1002, in _find_and_load_unlocked
  File "<frozen importlib._bootstrap>", line 941, in _find_spec
  File "<frozen importlib._bootstrap>", line 915, in _find_spec_legacy
  File "/workdir/oci-2.104.3/.tox/cpythonlibtest-unit-test-tests/lib/python3.10/site-packages/_pytest/assertion/rewrite.py", line 175, in find_module
    source_stat, co = _rewrite_test(self.config, fn_pypath)
  File "/workdir/oci-2.104.3/.tox/cpythonlibtest-unit-test-tests/lib/python3.10/site-packages/_pytest/assertion/rewrite.py", line 426, in _rewrite_test
    co = compile(tree, fn.strpath, "exec", dont_inherit=True)
TypeError: required field "lineno" missing from alias
ERROR: InvocationError for command /workdir/oci-2.104.3/.tox/cpythonlibtest-unit-test-tests/bin/pytest -v --tb=native --junitxml /workdir/results/oci/2.104.3/1/cpython-test-results.xml (exited with code 1)
___________________________________ summary ____________________________________
ERROR:   cpythonlibtest-unit-test-tests: commands failed
