GLOB sdist-make: /workdir/email-validator-1.3.1/setup.py
graalpylibtest-unit-test-tests create: /workdir/email-validator-1.3.1/.tox/graalpylibtest-unit-test-tests
graalpylibtest-unit-test-tests installdeps: mock, pytest, -rtest_requirements.txt
graalpylibtest-unit-test-tests inst: /workdir/email-validator-1.3.1/.tox/.tmp/package/1/email_validator-1.3.1.zip
graalpylibtest-unit-test-tests installed: attrs==21.4.0,coverage==6.2,dnspython==2.2.1,email-validator @ file:///workdir/email-validator-1.3.1/.tox/.tmp/package/1/email_validator-1.3.1.zip,flake8==4.0.1,graalpy-virtualenv==0.0.1,hpy==0.9.0rc2,idna==3.3,importlib-metadata==4.2.0,iniconfig==1.1.1,mccabe==0.6.1,mock==5.1.0,packaging==21.3,pluggy==1.0.0,py==1.11.0,pycodestyle==2.8.0,pyflakes==2.4.0,pyparsing==3.0.7,pytest==7.0.1,pytest-cov==3.0.0,tomli==1.2.3,typing_extensions==4.1.1,zipp==3.6.0
graalpylibtest-unit-test-tests run-test-pre: PYTHONHASHSEED='3421336381'
graalpylibtest-unit-test-tests run-test: commands[0] | pytest -v --tb=native --junitxml /workdir/results/email-validator/1.3.1/1/graalpy-test-results.xml
============================= test session starts ==============================
platform linux -- Python 3.10.8, pytest-7.0.1, pluggy-1.0.0 -- /workdir/email-validator-1.3.1/.tox/graalpylibtest-unit-test-tests/bin/python
cachedir: .tox/graalpylibtest-unit-test-tests/.pytest_cache
rootdir: /workdir/email-validator-1.3.1, configfile: setup.cfg, testpaths: tests
plugins: cov-3.0.0
collecting ... collected 0 items / 1 error

==================================== ERRORS ====================================
_____________________ ERROR collecting tests/test_main.py ______________________
Traceback (most recent call last):
  File "/workdir/email-validator-1.3.1/tests/test_main.py", line 1, in <module>
    import dns.resolver
  File "/workdir/email-validator-1.3.1/.tox/graalpylibtest-unit-test-tests/lib/python3.10/site-packages/dns/resolver.py", line 1325, in <module>
    _original_gethostbyname_ex = socket.gethostbyname_ex
AttributeError: module 'socket' has no attribute 'gethostbyname_ex'
- generated xml file: /workdir/results/email-validator/1.3.1/1/graalpy-test-results.xml -
=========================== short test summary info ============================
ERROR tests/test_main.py - AttributeError: module 'socket' has no attribute '...
!!!!!!!!!!!!!!!!!!!! Interrupted: 1 error during collection !!!!!!!!!!!!!!!!!!!!
=============================== 1 error in 0.59s ===============================
ERROR: InvocationError for command /workdir/email-validator-1.3.1/.tox/graalpylibtest-unit-test-tests/bin/pytest -v --tb=native --junitxml /workdir/results/email-validator/1.3.1/1/graalpy-test-results.xml (exited with code 2)
___________________________________ summary ____________________________________
ERROR:   graalpylibtest-unit-test-tests: commands failed
