GLOB sdist-make: /workdir/Faker-15.3.4/setup.py
cpythonlibtest-unit-test-tests create: /workdir/Faker-15.3.4/.tox/cpythonlibtest-unit-test-tests
cpythonlibtest-unit-test-tests installdeps: mock, pytest
cpythonlibtest-unit-test-tests inst: /workdir/Faker-15.3.4/.tox/.tmp/package/1/Faker-15.3.4.zip
cpythonlibtest-unit-test-tests installed: exceptiongroup==1.1.3,Faker @ file:///workdir/Faker-15.3.4/.tox/.tmp/package/1/Faker-15.3.4.zip#sha256=f61960ab602023dd24ff9c99430ca1882a91dcb8acbc68eda375431906caf260,iniconfig==2.0.0,mock==5.1.0,packaging==23.2,pluggy==1.3.0,pytest==7.4.3,python-dateutil==2.8.2,six==1.16.0,tomli==2.0.1
cpythonlibtest-unit-test-tests run-test-pre: PYTHONHASHSEED='2032597081'
cpythonlibtest-unit-test-tests run-test: commands[0] | pytest -v --tb=native --junitxml /workdir/results/Faker/15.3.4/1/cpython-test-results.xml
============================= test session starts ==============================
platform linux -- Python 3.10.8, pytest-7.4.3, pluggy-1.3.0 -- /workdir/Faker-15.3.4/.tox/cpythonlibtest-unit-test-tests/bin/python
cachedir: .tox/cpythonlibtest-unit-test-tests/.pytest_cache
rootdir: /workdir/Faker-15.3.4
configfile: setup.cfg
plugins: Faker-15.3.4
collecting ... collected 1350 items / 6 errors

==================================== ERRORS ====================================
______________ ERROR collecting tests/providers/test_date_time.py ______________
ImportError while importing test module '/workdir/Faker-15.3.4/tests/providers/test_date_time.py'.
Hint: make sure your test modules/packages have valid Python names.
Traceback:
.tox/cpythonlibtest-unit-test-tests/lib/python3.10/site-packages/_pytest/python.py:617: in _importtestmodule
    mod = import_path(self.path, mode=importmode, root=self.config.rootpath)
.tox/cpythonlibtest-unit-test-tests/lib/python3.10/site-packages/_pytest/pathlib.py:567: in import_path
    importlib.import_module(module_name)
/usr/local/lib/python3.10/importlib/__init__.py:126: in import_module
    return _bootstrap._gcd_import(name[level:], package, level)
<frozen importlib._bootstrap>:1050: in _gcd_import
    ???
<frozen importlib._bootstrap>:1027: in _find_and_load
    ???
<frozen importlib._bootstrap>:1006: in _find_and_load_unlocked
    ???
<frozen importlib._bootstrap>:688: in _load_unlocked
    ???
.tox/cpythonlibtest-unit-test-tests/lib/python3.10/site-packages/_pytest/assertion/rewrite.py:186: in exec_module
    exec(co, module.__dict__)
tests/providers/test_date_time.py:13: in <module>
    import freezegun
E   ModuleNotFoundError: No module named 'freezegun'
______________ ERROR collecting tests/providers/test_internet.py _______________
ImportError while importing test module '/workdir/Faker-15.3.4/tests/providers/test_internet.py'.
Hint: make sure your test modules/packages have valid Python names.
Traceback:
.tox/cpythonlibtest-unit-test-tests/lib/python3.10/site-packages/_pytest/python.py:617: in _importtestmodule
    mod = import_path(self.path, mode=importmode, root=self.config.rootpath)
.tox/cpythonlibtest-unit-test-tests/lib/python3.10/site-packages/_pytest/pathlib.py:567: in import_path
    importlib.import_module(module_name)
/usr/local/lib/python3.10/importlib/__init__.py:126: in import_module
    return _bootstrap._gcd_import(name[level:], package, level)
<frozen importlib._bootstrap>:1050: in _gcd_import
    ???
<frozen importlib._bootstrap>:1027: in _find_and_load
    ???
<frozen importlib._bootstrap>:1006: in _find_and_load_unlocked
    ???
<frozen importlib._bootstrap>:688: in _load_unlocked
    ???
.tox/cpythonlibtest-unit-test-tests/lib/python3.10/site-packages/_pytest/assertion/rewrite.py:186: in exec_module
    exec(co, module.__dict__)
tests/providers/test_internet.py:10: in <module>
    from validators import domain as validate_domain
E   ModuleNotFoundError: No module named 'validators'
_________________ ERROR collecting tests/providers/test_ssn.py _________________
ImportError while importing test module '/workdir/Faker-15.3.4/tests/providers/test_ssn.py'.
Hint: make sure your test modules/packages have valid Python names.
Traceback:
.tox/cpythonlibtest-unit-test-tests/lib/python3.10/site-packages/_pytest/python.py:617: in _importtestmodule
    mod = import_path(self.path, mode=importmode, root=self.config.rootpath)
.tox/cpythonlibtest-unit-test-tests/lib/python3.10/site-packages/_pytest/pathlib.py:567: in import_path
    importlib.import_module(module_name)
/usr/local/lib/python3.10/importlib/__init__.py:126: in import_module
    return _bootstrap._gcd_import(name[level:], package, level)
<frozen importlib._bootstrap>:1050: in _gcd_import
    ???
<frozen importlib._bootstrap>:1027: in _find_and_load
    ???
<frozen importlib._bootstrap>:1006: in _find_and_load_unlocked
    ???
<frozen importlib._bootstrap>:688: in _load_unlocked
    ???
.tox/cpythonlibtest-unit-test-tests/lib/python3.10/site-packages/_pytest/assertion/rewrite.py:186: in exec_module
    exec(co, module.__dict__)
tests/providers/test_ssn.py:10: in <module>
    import freezegun
E   ModuleNotFoundError: No module named 'freezegun'
_____________ ERROR collecting tests/providers/test_user_agent.py ______________
ImportError while importing test module '/workdir/Faker-15.3.4/tests/providers/test_user_agent.py'.
Hint: make sure your test modules/packages have valid Python names.
Traceback:
.tox/cpythonlibtest-unit-test-tests/lib/python3.10/site-packages/_pytest/python.py:617: in _importtestmodule
    mod = import_path(self.path, mode=importmode, root=self.config.rootpath)
.tox/cpythonlibtest-unit-test-tests/lib/python3.10/site-packages/_pytest/pathlib.py:567: in import_path
    importlib.import_module(module_name)
/usr/local/lib/python3.10/importlib/__init__.py:126: in import_module
    return _bootstrap._gcd_import(name[level:], package, level)
<frozen importlib._bootstrap>:1050: in _gcd_import
    ???
<frozen importlib._bootstrap>:1027: in _find_and_load
    ???
<frozen importlib._bootstrap>:1006: in _find_and_load_unlocked
    ???
<frozen importlib._bootstrap>:688: in _load_unlocked
    ???
.tox/cpythonlibtest-unit-test-tests/lib/python3.10/site-packages/_pytest/assertion/rewrite.py:186: in exec_module
    exec(co, module.__dict__)
tests/providers/test_user_agent.py:6: in <module>
    from freezegun import freeze_time
E   ModuleNotFoundError: No module named 'freezegun'
_______________ ERROR collecting tests/sphinx/test_docstring.py ________________
ImportError while importing test module '/workdir/Faker-15.3.4/tests/sphinx/test_docstring.py'.
Hint: make sure your test modules/packages have valid Python names.
Traceback:
.tox/cpythonlibtest-unit-test-tests/lib/python3.10/site-packages/_pytest/python.py:617: in _importtestmodule
    mod = import_path(self.path, mode=importmode, root=self.config.rootpath)
.tox/cpythonlibtest-unit-test-tests/lib/python3.10/site-packages/_pytest/pathlib.py:567: in import_path
    importlib.import_module(module_name)
/usr/local/lib/python3.10/importlib/__init__.py:126: in import_module
    return _bootstrap._gcd_import(name[level:], package, level)
<frozen importlib._bootstrap>:1050: in _gcd_import
    ???
<frozen importlib._bootstrap>:1027: in _find_and_load
    ???
<frozen importlib._bootstrap>:1006: in _find_and_load_unlocked
    ???
<frozen importlib._bootstrap>:688: in _load_unlocked
    ???
.tox/cpythonlibtest-unit-test-tests/lib/python3.10/site-packages/_pytest/assertion/rewrite.py:186: in exec_module
    exec(co, module.__dict__)
tests/sphinx/test_docstring.py:8: in <module>
    from faker.sphinx.docstring import DEFAULT_SAMPLE_SIZE, DEFAULT_SEED, ProviderMethodDocstring, Sample
E   ModuleNotFoundError: No module named 'faker.sphinx'
_______________ ERROR collecting tests/sphinx/test_validator.py ________________
ImportError while importing test module '/workdir/Faker-15.3.4/tests/sphinx/test_validator.py'.
Hint: make sure your test modules/packages have valid Python names.
Traceback:
.tox/cpythonlibtest-unit-test-tests/lib/python3.10/site-packages/_pytest/python.py:617: in _importtestmodule
    mod = import_path(self.path, mode=importmode, root=self.config.rootpath)
.tox/cpythonlibtest-unit-test-tests/lib/python3.10/site-packages/_pytest/pathlib.py:567: in import_path
    importlib.import_module(module_name)
/usr/local/lib/python3.10/importlib/__init__.py:126: in import_module
    return _bootstrap._gcd_import(name[level:], package, level)
<frozen importlib._bootstrap>:1050: in _gcd_import
    ???
<frozen importlib._bootstrap>:1027: in _find_and_load
    ???
<frozen importlib._bootstrap>:1006: in _find_and_load_unlocked
    ???
<frozen importlib._bootstrap>:688: in _load_unlocked
    ???
.tox/cpythonlibtest-unit-test-tests/lib/python3.10/site-packages/_pytest/assertion/rewrite.py:186: in exec_module
    exec(co, module.__dict__)
tests/sphinx/test_validator.py:6: in <module>
    from faker.sphinx.validator import SampleCodeValidator
E   ModuleNotFoundError: No module named 'faker.sphinx'
- generated xml file: /workdir/results/Faker/15.3.4/1/cpython-test-results.xml -
=========================== short test summary info ============================
ERROR tests/providers/test_date_time.py
ERROR tests/providers/test_internet.py
ERROR tests/providers/test_ssn.py
ERROR tests/providers/test_user_agent.py
ERROR tests/sphinx/test_docstring.py
ERROR tests/sphinx/test_validator.py
!!!!!!!!!!!!!!!!!!! Interrupted: 6 errors during collection !!!!!!!!!!!!!!!!!!!!
============================== 6 errors in 4.95s ===============================
ERROR: InvocationError for command /workdir/Faker-15.3.4/.tox/cpythonlibtest-unit-test-tests/bin/pytest -v --tb=native --junitxml /workdir/results/Faker/15.3.4/1/cpython-test-results.xml (exited with code 2)
___________________________________ summary ____________________________________
ERROR:   cpythonlibtest-unit-test-tests: commands failed
