GLOB sdist-make: /workdir/lightfm-1.17/setup.py
cpythonlibtest-unit-test-tests create: /workdir/lightfm-1.17/.tox/cpythonlibtest-unit-test-tests
cpythonlibtest-unit-test-tests installdeps: mock, pytest, -rtest-requirements.txt, -rlint-requirements.txt
cpythonlibtest-unit-test-tests inst: /workdir/lightfm-1.17/.tox/.tmp/package/1/lightfm-1.17.zip
cpythonlibtest-unit-test-tests installed: black==22.1.0,certifi==2023.11.17,cfgv==3.4.0,charset-normalizer==3.3.2,click==8.1.7,distlib==0.3.7,exceptiongroup==1.2.0,filelock==3.13.1,flake8==4.0.1,identify==2.5.32,idna==3.4,iniconfig==2.0.0,joblib==1.3.2,lightfm @ file:///workdir/lightfm-1.17/.tox/.tmp/package/1/lightfm-1.17.zip#sha256=e826d8337dacfe3188af0ad534a7f6397af50109584c8e9a7222e0738074694f,mccabe==0.6.1,mock==5.1.0,mypy-extensions==1.0.0,nodeenv==1.8.0,numpy==1.26.2,packaging==23.2,pathspec==0.11.2,platformdirs==4.0.0,pluggy==1.3.0,pre-commit==2.17.0,pycodestyle==2.8.0,pyflakes==2.4.0,pytest==7.4.3,PyYAML==6.0.1,requests==2.31.0,scikit-learn==1.3.2,scipy==1.11.4,threadpoolctl==3.2.0,toml==0.10.2,tomli==2.0.1,urllib3==2.1.0,virtualenv==20.24.7
cpythonlibtest-unit-test-tests run-test-pre: PYTHONHASHSEED='256460641'
cpythonlibtest-unit-test-tests run-test: commands[0] | pytest -v --tb=native --junitxml /workdir/results/lightfm/1.17/1/cpython-test-results.xml
============================= test session starts ==============================
platform linux -- Python 3.10.8, pytest-7.4.3, pluggy-1.3.0 -- /workdir/lightfm-1.17/.tox/cpythonlibtest-unit-test-tests/bin/python
cachedir: .tox/cpythonlibtest-unit-test-tests/.pytest_cache
rootdir: /workdir/lightfm-1.17
collecting ... collected 0 items / 7 errors

==================================== ERRORS ====================================
______________________ ERROR collecting tests/test_api.py ______________________
ImportError while importing test module '/workdir/lightfm-1.17/tests/test_api.py'.
Hint: make sure your test modules/packages have valid Python names.
Traceback:
lightfm/__init__.py:2: in <module>
    __LIGHTFM_SETUP__
E   NameError: name '__LIGHTFM_SETUP__' is not defined

During handling of the above exception, another exception occurred:
lightfm/_lightfm_fast.py:3: in <module>
    from ._lightfm_fast_openmp import *  # NOQA
E   ModuleNotFoundError: No module named 'lightfm._lightfm_fast_openmp'

During handling of the above exception, another exception occurred:
/usr/local/lib/python3.10/importlib/__init__.py:126: in import_module
    return _bootstrap._gcd_import(name[level:], package, level)
tests/test_api.py:7: in <module>
    from lightfm.lightfm import LightFM
lightfm/__init__.py:4: in <module>
    from .lightfm import LightFM
lightfm/lightfm.py:8: in <module>
    from ._lightfm_fast import (
lightfm/_lightfm_fast.py:14: in <module>
    from ._lightfm_fast_no_openmp import *  # NOQA
E   ModuleNotFoundError: No module named 'lightfm._lightfm_fast_no_openmp'
_______________ ERROR collecting tests/test_cross_validation.py ________________
ImportError while importing test module '/workdir/lightfm-1.17/tests/test_cross_validation.py'.
Hint: make sure your test modules/packages have valid Python names.
Traceback:
lightfm/__init__.py:2: in <module>
    __LIGHTFM_SETUP__
E   NameError: name '__LIGHTFM_SETUP__' is not defined

During handling of the above exception, another exception occurred:
lightfm/_lightfm_fast.py:3: in <module>
    from ._lightfm_fast_openmp import *  # NOQA
E   ModuleNotFoundError: No module named 'lightfm._lightfm_fast_openmp'

During handling of the above exception, another exception occurred:
/usr/local/lib/python3.10/importlib/__init__.py:126: in import_module
    return _bootstrap._gcd_import(name[level:], package, level)
tests/test_cross_validation.py:3: in <module>
    from lightfm.cross_validation import random_train_test_split
lightfm/__init__.py:4: in <module>
    from .lightfm import LightFM
lightfm/lightfm.py:8: in <module>
    from ._lightfm_fast import (
lightfm/_lightfm_fast.py:14: in <module>
    from ._lightfm_fast_no_openmp import *  # NOQA
E   ModuleNotFoundError: No module named 'lightfm._lightfm_fast_no_openmp'
_____________________ ERROR collecting tests/test_data.py ______________________
ImportError while importing test module '/workdir/lightfm-1.17/tests/test_data.py'.
Hint: make sure your test modules/packages have valid Python names.
Traceback:
lightfm/__init__.py:2: in <module>
    __LIGHTFM_SETUP__
E   NameError: name '__LIGHTFM_SETUP__' is not defined

During handling of the above exception, another exception occurred:
lightfm/_lightfm_fast.py:3: in <module>
    from ._lightfm_fast_openmp import *  # NOQA
E   ModuleNotFoundError: No module named 'lightfm._lightfm_fast_openmp'

During handling of the above exception, another exception occurred:
/usr/local/lib/python3.10/importlib/__init__.py:126: in import_module
    return _bootstrap._gcd_import(name[level:], package, level)
tests/test_data.py:4: in <module>
    from lightfm.data import Dataset
lightfm/__init__.py:4: in <module>
    from .lightfm import LightFM
lightfm/lightfm.py:8: in <module>
    from ._lightfm_fast import (
lightfm/_lightfm_fast.py:14: in <module>
    from ._lightfm_fast_no_openmp import *  # NOQA
E   ModuleNotFoundError: No module named 'lightfm._lightfm_fast_no_openmp'
___________________ ERROR collecting tests/test_datasets.py ____________________
ImportError while importing test module '/workdir/lightfm-1.17/tests/test_datasets.py'.
Hint: make sure your test modules/packages have valid Python names.
Traceback:
lightfm/__init__.py:2: in <module>
    __LIGHTFM_SETUP__
E   NameError: name '__LIGHTFM_SETUP__' is not defined

During handling of the above exception, another exception occurred:
lightfm/_lightfm_fast.py:3: in <module>
    from ._lightfm_fast_openmp import *  # NOQA
E   ModuleNotFoundError: No module named 'lightfm._lightfm_fast_openmp'

During handling of the above exception, another exception occurred:
/usr/local/lib/python3.10/importlib/__init__.py:126: in import_module
    return _bootstrap._gcd_import(name[level:], package, level)
tests/test_datasets.py:7: in <module>
    from lightfm.datasets import fetch_movielens, fetch_stackexchange
lightfm/__init__.py:4: in <module>
    from .lightfm import LightFM
lightfm/lightfm.py:8: in <module>
    from ._lightfm_fast import (
lightfm/_lightfm_fast.py:14: in <module>
    from ._lightfm_fast_no_openmp import *  # NOQA
E   ModuleNotFoundError: No module named 'lightfm._lightfm_fast_no_openmp'
__________________ ERROR collecting tests/test_evaluation.py ___________________
ImportError while importing test module '/workdir/lightfm-1.17/tests/test_evaluation.py'.
Hint: make sure your test modules/packages have valid Python names.
Traceback:
lightfm/__init__.py:2: in <module>
    __LIGHTFM_SETUP__
E   NameError: name '__LIGHTFM_SETUP__' is not defined

During handling of the above exception, another exception occurred:
lightfm/_lightfm_fast.py:3: in <module>
    from ._lightfm_fast_openmp import *  # NOQA
E   ModuleNotFoundError: No module named 'lightfm._lightfm_fast_openmp'

During handling of the above exception, another exception occurred:
/usr/local/lib/python3.10/importlib/__init__.py:126: in import_module
    return _bootstrap._gcd_import(name[level:], package, level)
tests/test_evaluation.py:9: in <module>
    from lightfm.lightfm import LightFM
lightfm/__init__.py:4: in <module>
    from .lightfm import LightFM
lightfm/lightfm.py:8: in <module>
    from ._lightfm_fast import (
lightfm/_lightfm_fast.py:14: in <module>
    from ._lightfm_fast_no_openmp import *  # NOQA
E   ModuleNotFoundError: No module named 'lightfm._lightfm_fast_no_openmp'
________________ ERROR collecting tests/test_fast_functions.py _________________
ImportError while importing test module '/workdir/lightfm-1.17/tests/test_fast_functions.py'.
Hint: make sure your test modules/packages have valid Python names.
Traceback:
lightfm/__init__.py:2: in <module>
    __LIGHTFM_SETUP__
E   NameError: name '__LIGHTFM_SETUP__' is not defined

During handling of the above exception, another exception occurred:
lightfm/_lightfm_fast.py:3: in <module>
    from ._lightfm_fast_openmp import *  # NOQA
E   ModuleNotFoundError: No module named 'lightfm._lightfm_fast_openmp'

During handling of the above exception, another exception occurred:
/usr/local/lib/python3.10/importlib/__init__.py:126: in import_module
    return _bootstrap._gcd_import(name[level:], package, level)
tests/test_fast_functions.py:6: in <module>
    from lightfm import _lightfm_fast
lightfm/__init__.py:4: in <module>
    from .lightfm import LightFM
lightfm/lightfm.py:8: in <module>
    from ._lightfm_fast import (
lightfm/_lightfm_fast.py:14: in <module>
    from ._lightfm_fast_no_openmp import *  # NOQA
E   ModuleNotFoundError: No module named 'lightfm._lightfm_fast_no_openmp'
___________________ ERROR collecting tests/test_movielens.py ___________________
ImportError while importing test module '/workdir/lightfm-1.17/tests/test_movielens.py'.
Hint: make sure your test modules/packages have valid Python names.
Traceback:
lightfm/__init__.py:2: in <module>
    __LIGHTFM_SETUP__
E   NameError: name '__LIGHTFM_SETUP__' is not defined

During handling of the above exception, another exception occurred:
lightfm/_lightfm_fast.py:3: in <module>
    from ._lightfm_fast_openmp import *  # NOQA
E   ModuleNotFoundError: No module named 'lightfm._lightfm_fast_openmp'

During handling of the above exception, another exception occurred:
/usr/local/lib/python3.10/importlib/__init__.py:126: in import_module
    return _bootstrap._gcd_import(name[level:], package, level)
tests/test_movielens.py:11: in <module>
    from lightfm.lightfm import LightFM
lightfm/__init__.py:4: in <module>
    from .lightfm import LightFM
lightfm/lightfm.py:8: in <module>
    from ._lightfm_fast import (
lightfm/_lightfm_fast.py:14: in <module>
    from ._lightfm_fast_no_openmp import *  # NOQA
E   ModuleNotFoundError: No module named 'lightfm._lightfm_fast_no_openmp'
=============================== warnings summary ===============================
lightfm/_lightfm_fast.py:9
lightfm/_lightfm_fast.py:9
lightfm/_lightfm_fast.py:9
lightfm/_lightfm_fast.py:9
lightfm/_lightfm_fast.py:9
lightfm/_lightfm_fast.py:9
lightfm/_lightfm_fast.py:9
  /workdir/lightfm-1.17/lightfm/_lightfm_fast.py:9: UserWarning: LightFM was compiled without OpenMP support. Only a single thread will be used.
    warnings.warn(

-- Docs: https://docs.pytest.org/en/stable/how-to/capture-warnings.html
- generated xml file: /workdir/results/lightfm/1.17/1/cpython-test-results.xml -
=========================== short test summary info ============================
ERROR tests/test_api.py
ERROR tests/test_cross_validation.py
ERROR tests/test_data.py
ERROR tests/test_datasets.py
ERROR tests/test_evaluation.py
ERROR tests/test_fast_functions.py
ERROR tests/test_movielens.py
!!!!!!!!!!!!!!!!!!! Interrupted: 7 errors during collection !!!!!!!!!!!!!!!!!!!!
======================== 7 warnings, 7 errors in 0.84s =========================
ERROR: InvocationError for command /workdir/lightfm-1.17/.tox/cpythonlibtest-unit-test-tests/bin/pytest -v --tb=native --junitxml /workdir/results/lightfm/1.17/1/cpython-test-results.xml (exited with code 2)
___________________________________ summary ____________________________________
ERROR:   cpythonlibtest-unit-test-tests: commands failed
