.package create: /workdir/py-1.11.0/.tox/.package
.package installdeps: setuptools, setuptools_scm[toml]
/workdir/py-1.11.0/.tox/.package/lib/python3.10/site-packages/setuptools/config/setupcfg.py:463: SetuptoolsDeprecationWarning: The license_file parameter is deprecated, use license_files instead.
  warnings.warn(msg, warning_class)
WARNING setuptools_scm.pyproject_reading toml section missing 'pyproject.toml does not contain a tool.setuptools_scm section'
/workdir/py-1.11.0/.tox/.package/lib/python3.10/site-packages/setuptools_scm/git.py:163: UserWarning: "/workdir/py-1.11.0" is shallow and may cause errors
  warnings.warn(f'"{wd.path}" is shallow and may cause errors')
/workdir/py-1.11.0/.tox/.package/lib/python3.10/site-packages/setuptools/config/setupcfg.py:463: SetuptoolsDeprecationWarning: The license_file parameter is deprecated, use license_files instead.
  warnings.warn(msg, warning_class)
warning: no previously-included files matching '*.pyc' found anywhere in distribution
cpythonlibtest-unit-test-tests create: /workdir/py-1.11.0/.tox/cpythonlibtest-unit-test-tests
cpythonlibtest-unit-test-tests installdeps: mock, pytest
cpythonlibtest-unit-test-tests inst: /workdir/py-1.11.0/.tox/.tmp/package/1/py-1.11.0.tar.gz
cpythonlibtest-unit-test-tests installed: exceptiongroup==1.2.0,iniconfig==2.0.0,mock==5.1.0,packaging==23.2,pluggy==1.3.0,py @ file:///workdir/py-1.11.0/.tox/.tmp/package/1/py-1.11.0.tar.gz#sha256=afbd669856b4185bc73b065b5749dce9194c163ce4e2cceccdbd2cdcf00fdb89,pytest==7.4.3,tomli==2.0.1
cpythonlibtest-unit-test-tests run-test-pre: PYTHONHASHSEED='848015476'
cpythonlibtest-unit-test-tests run-test: commands[0] | pytest -v --tb=native --junitxml /workdir/results/py/1.11.0/1/cpython-test-results.xml
============================= test session starts ==============================
platform linux -- Python 3.10.8, pytest-7.4.3, pluggy-1.3.0 -- /workdir/py-1.11.0/.tox/cpythonlibtest-unit-test-tests/bin/python
cachedir: .tox/cpythonlibtest-unit-test-tests/.pytest_cache
rootdir: /workdir/py-1.11.0
configfile: tox.ini
testpaths: testing
collecting ... collected 832 items / 1 error
INTERNALERROR> Traceback (most recent call last):
INTERNALERROR>   File "/workdir/py-1.11.0/.tox/cpythonlibtest-unit-test-tests/lib/python3.10/site-packages/_pytest/main.py", line 271, in wrap_session
INTERNALERROR>     session.exitstatus = doit(config, session) or 0
INTERNALERROR>   File "/workdir/py-1.11.0/.tox/cpythonlibtest-unit-test-tests/lib/python3.10/site-packages/_pytest/main.py", line 324, in _main
INTERNALERROR>     config.hook.pytest_collection(session=session)
INTERNALERROR>   File "/workdir/py-1.11.0/.tox/cpythonlibtest-unit-test-tests/lib/python3.10/site-packages/pluggy/_hooks.py", line 493, in __call__
INTERNALERROR>     return self._hookexec(self.name, self._hookimpls, kwargs, firstresult)
INTERNALERROR>   File "/workdir/py-1.11.0/.tox/cpythonlibtest-unit-test-tests/lib/python3.10/site-packages/pluggy/_manager.py", line 115, in _hookexec
INTERNALERROR>     return self._inner_hookexec(hook_name, methods, kwargs, firstresult)
INTERNALERROR>   File "/workdir/py-1.11.0/.tox/cpythonlibtest-unit-test-tests/lib/python3.10/site-packages/pluggy/_callers.py", line 152, in _multicall
INTERNALERROR>     return outcome.get_result()
INTERNALERROR>   File "/workdir/py-1.11.0/.tox/cpythonlibtest-unit-test-tests/lib/python3.10/site-packages/pluggy/_result.py", line 114, in get_result
INTERNALERROR>     raise exc.with_traceback(exc.__traceback__)
INTERNALERROR>   File "/workdir/py-1.11.0/.tox/cpythonlibtest-unit-test-tests/lib/python3.10/site-packages/pluggy/_callers.py", line 77, in _multicall
INTERNALERROR>     res = hook_impl.function(*args)
INTERNALERROR>   File "/workdir/py-1.11.0/.tox/cpythonlibtest-unit-test-tests/lib/python3.10/site-packages/_pytest/main.py", line 335, in pytest_collection
INTERNALERROR>     session.perform_collect()
INTERNALERROR>   File "/workdir/py-1.11.0/.tox/cpythonlibtest-unit-test-tests/lib/python3.10/site-packages/_pytest/main.py", line 677, in perform_collect
INTERNALERROR>     self.config.pluginmanager.check_pending()
INTERNALERROR>   File "/workdir/py-1.11.0/.tox/cpythonlibtest-unit-test-tests/lib/python3.10/site-packages/pluggy/_manager.py", line 370, in check_pending
INTERNALERROR>     raise PluginValidationError(
INTERNALERROR> pluggy._manager.PluginValidationError: unknown hook 'pytest_funcarg__repowc1' in plugin <module 'conftest' from '/workdir/py-1.11.0/testing/path/conftest.py'>

========================= 6 warnings, 1 error in 1.02s =========================
ERROR: InvocationError for command /workdir/py-1.11.0/.tox/cpythonlibtest-unit-test-tests/bin/pytest -v --tb=native --junitxml /workdir/results/py/1.11.0/1/cpython-test-results.xml (exited with code 3)
___________________________________ summary ____________________________________
ERROR:   cpythonlibtest-unit-test-tests: commands failed
