<?xml version="1.0" encoding="utf-8"?><testsuites><testsuite name="pytest" errors="3" failures="0" skipped="0" tests="3" time="0.872" timestamp="2023-11-29T05:11:07.687000" hostname="a1f8948d47fc"><testcase classname="" name="s3fs.tests.test_mapping" time="0.000"><error message="collection failure">Traceback (most recent call last):
  File "/workdir/s3fs-2022.11.0/.tox/graalpylibtest-unit-test-tests/lib/python3.10/site-packages/_pytest/runner.py", line 341, in from_call
    result: Optional[TResult] = func()
  File "/workdir/s3fs-2022.11.0/.tox/graalpylibtest-unit-test-tests/lib/python3.10/site-packages/_pytest/runner.py", line 372, in &lt;lambda&gt;
    call = CallInfo.from_call(lambda: list(collector.collect()), "collect")
  File "/workdir/s3fs-2022.11.0/.tox/graalpylibtest-unit-test-tests/lib/python3.10/site-packages/_pytest/python.py", line 531, in collect
    self._inject_setup_module_fixture()
  File "/workdir/s3fs-2022.11.0/.tox/graalpylibtest-unit-test-tests/lib/python3.10/site-packages/_pytest/python.py", line 545, in _inject_setup_module_fixture
    self.obj, ("setUpModule", "setup_module")
  File "/workdir/s3fs-2022.11.0/.tox/graalpylibtest-unit-test-tests/lib/python3.10/site-packages/_pytest/python.py", line 310, in obj
    self._obj = obj = self._getobj()
  File "/workdir/s3fs-2022.11.0/.tox/graalpylibtest-unit-test-tests/lib/python3.10/site-packages/_pytest/python.py", line 528, in _getobj
    return self._importtestmodule()
  File "/workdir/s3fs-2022.11.0/.tox/graalpylibtest-unit-test-tests/lib/python3.10/site-packages/_pytest/python.py", line 617, in _importtestmodule
    mod = import_path(self.path, mode=importmode, root=self.config.rootpath)
  File "/workdir/s3fs-2022.11.0/.tox/graalpylibtest-unit-test-tests/lib/python3.10/site-packages/_pytest/pathlib.py", line 567, in import_path
    importlib.import_module(module_name)
  File "/opt/graalpy/lib/python3.10/importlib/__init__.py", line 126, in import_module
    return _bootstrap._gcd_import(name[level:], package, level)
  File "/workdir/s3fs-2022.11.0/s3fs/__init__.py", line 1, in &lt;module&gt;
    from .core import S3FileSystem, S3File
  File "/workdir/s3fs-2022.11.0/s3fs/core.py", line 17, in &lt;module&gt;
    from fsspec.asyn import (
  File "/workdir/s3fs-2022.11.0/.tox/graalpylibtest-unit-test-tests/lib/python3.10/site-packages/fsspec/asyn.py", line 189, in &lt;module&gt;
    ResourceEror = resource.error
AttributeError: module 'resource' has no attribute 'error'</error></testcase><testcase classname="" name="s3fs.tests.test_s3fs" time="0.000"><error message="collection failure">Traceback (most recent call last):
  File "/workdir/s3fs-2022.11.0/.tox/graalpylibtest-unit-test-tests/lib/python3.10/site-packages/_pytest/runner.py", line 341, in from_call
    result: Optional[TResult] = func()
  File "/workdir/s3fs-2022.11.0/.tox/graalpylibtest-unit-test-tests/lib/python3.10/site-packages/_pytest/runner.py", line 372, in &lt;lambda&gt;
    call = CallInfo.from_call(lambda: list(collector.collect()), "collect")
  File "/workdir/s3fs-2022.11.0/.tox/graalpylibtest-unit-test-tests/lib/python3.10/site-packages/_pytest/python.py", line 531, in collect
    self._inject_setup_module_fixture()
  File "/workdir/s3fs-2022.11.0/.tox/graalpylibtest-unit-test-tests/lib/python3.10/site-packages/_pytest/python.py", line 545, in _inject_setup_module_fixture
    self.obj, ("setUpModule", "setup_module")
  File "/workdir/s3fs-2022.11.0/.tox/graalpylibtest-unit-test-tests/lib/python3.10/site-packages/_pytest/python.py", line 310, in obj
    self._obj = obj = self._getobj()
  File "/workdir/s3fs-2022.11.0/.tox/graalpylibtest-unit-test-tests/lib/python3.10/site-packages/_pytest/python.py", line 528, in _getobj
    return self._importtestmodule()
  File "/workdir/s3fs-2022.11.0/.tox/graalpylibtest-unit-test-tests/lib/python3.10/site-packages/_pytest/python.py", line 617, in _importtestmodule
    mod = import_path(self.path, mode=importmode, root=self.config.rootpath)
  File "/workdir/s3fs-2022.11.0/.tox/graalpylibtest-unit-test-tests/lib/python3.10/site-packages/_pytest/pathlib.py", line 567, in import_path
    importlib.import_module(module_name)
  File "/opt/graalpy/lib/python3.10/importlib/__init__.py", line 126, in import_module
    return _bootstrap._gcd_import(name[level:], package, level)
  File "/workdir/s3fs-2022.11.0/s3fs/__init__.py", line 1, in &lt;module&gt;
    from .core import S3FileSystem, S3File
  File "/workdir/s3fs-2022.11.0/s3fs/core.py", line 17, in &lt;module&gt;
    from fsspec.asyn import (
  File "/workdir/s3fs-2022.11.0/.tox/graalpylibtest-unit-test-tests/lib/python3.10/site-packages/fsspec/asyn.py", line 189, in &lt;module&gt;
    ResourceEror = resource.error
AttributeError: module 'resource' has no attribute 'error'</error></testcase><testcase classname="" name="s3fs.tests.test_utils" time="0.000"><error message="collection failure">Traceback (most recent call last):
  File "/workdir/s3fs-2022.11.0/.tox/graalpylibtest-unit-test-tests/lib/python3.10/site-packages/_pytest/runner.py", line 341, in from_call
    result: Optional[TResult] = func()
  File "/workdir/s3fs-2022.11.0/.tox/graalpylibtest-unit-test-tests/lib/python3.10/site-packages/_pytest/runner.py", line 372, in &lt;lambda&gt;
    call = CallInfo.from_call(lambda: list(collector.collect()), "collect")
  File "/workdir/s3fs-2022.11.0/.tox/graalpylibtest-unit-test-tests/lib/python3.10/site-packages/_pytest/python.py", line 531, in collect
    self._inject_setup_module_fixture()
  File "/workdir/s3fs-2022.11.0/.tox/graalpylibtest-unit-test-tests/lib/python3.10/site-packages/_pytest/python.py", line 545, in _inject_setup_module_fixture
    self.obj, ("setUpModule", "setup_module")
  File "/workdir/s3fs-2022.11.0/.tox/graalpylibtest-unit-test-tests/lib/python3.10/site-packages/_pytest/python.py", line 310, in obj
    self._obj = obj = self._getobj()
  File "/workdir/s3fs-2022.11.0/.tox/graalpylibtest-unit-test-tests/lib/python3.10/site-packages/_pytest/python.py", line 528, in _getobj
    return self._importtestmodule()
  File "/workdir/s3fs-2022.11.0/.tox/graalpylibtest-unit-test-tests/lib/python3.10/site-packages/_pytest/python.py", line 617, in _importtestmodule
    mod = import_path(self.path, mode=importmode, root=self.config.rootpath)
  File "/workdir/s3fs-2022.11.0/.tox/graalpylibtest-unit-test-tests/lib/python3.10/site-packages/_pytest/pathlib.py", line 567, in import_path
    importlib.import_module(module_name)
  File "/opt/graalpy/lib/python3.10/importlib/__init__.py", line 126, in import_module
    return _bootstrap._gcd_import(name[level:], package, level)
  File "/workdir/s3fs-2022.11.0/s3fs/__init__.py", line 1, in &lt;module&gt;
    from .core import S3FileSystem, S3File
  File "/workdir/s3fs-2022.11.0/s3fs/core.py", line 17, in &lt;module&gt;
    from fsspec.asyn import (
  File "/workdir/s3fs-2022.11.0/.tox/graalpylibtest-unit-test-tests/lib/python3.10/site-packages/fsspec/asyn.py", line 189, in &lt;module&gt;
    ResourceEror = resource.error
AttributeError: module 'resource' has no attribute 'error'</error></testcase></testsuite></testsuites>