.package create: /workdir/setuptools-65.6.3/.tox/.package
warning: no files found matching '*.py' under directory 'tests'
warning: no files found matching '*.txt' under directory 'docs'
warning: no files found matching '*.conf' under directory 'docs'
warning: no files found matching '*.css' under directory 'docs'
warning: no files found matching '*.css_t' under directory 'docs'
warning: no files found matching 'Makefile' under directory 'docs'
warning: no files found matching 'indexsidebar.html' under directory 'docs'
warning: no files found matching 'msvc-build-launcher.cmd'
warning: no files found matching '*.py' under directory 'tests'
warning: no files found matching '*.txt' under directory 'docs'
warning: no files found matching '*.conf' under directory 'docs'
warning: no files found matching '*.css' under directory 'docs'
warning: no files found matching '*.css_t' under directory 'docs'
warning: no files found matching 'Makefile' under directory 'docs'
warning: no files found matching 'indexsidebar.html' under directory 'docs'
warning: no files found matching 'msvc-build-launcher.cmd'
cpythonlibtest-unit-test-tests create: /workdir/setuptools-65.6.3/.tox/cpythonlibtest-unit-test-tests
cpythonlibtest-unit-test-tests installdeps: mock, pytest
cpythonlibtest-unit-test-tests inst: /workdir/setuptools-65.6.3/.tox/.tmp/package/1/setuptools-65.6.3.post20231129.tar.gz
cpythonlibtest-unit-test-tests installed: exceptiongroup==1.2.0,iniconfig==2.0.0,mock==5.1.0,packaging==23.2,pluggy==1.3.0,pytest==7.4.3,tomli==2.0.1
cpythonlibtest-unit-test-tests run-test-pre: PYTHONHASHSEED='2226461471'
cpythonlibtest-unit-test-tests run-test: commands[0] | pytest -v --tb=native --junitxml /workdir/results/setuptools/65.6.3/1/cpython-test-results.xml
Traceback (most recent call last):
  File "/workdir/setuptools-65.6.3/.tox/cpythonlibtest-unit-test-tests/lib/python3.10/site-packages/_pytest/config/__init__.py", line 781, in import_plugin
    __import__(importspec)
ModuleNotFoundError: No module named 'setuptools.tests'

The above exception was the direct cause of the following exception:

Traceback (most recent call last):
  File "/workdir/setuptools-65.6.3/.tox/cpythonlibtest-unit-test-tests/bin/pytest", line 8, in <module>
    sys.exit(console_main())
  File "/workdir/setuptools-65.6.3/.tox/cpythonlibtest-unit-test-tests/lib/python3.10/site-packages/_pytest/config/__init__.py", line 192, in console_main
    code = main()
  File "/workdir/setuptools-65.6.3/.tox/cpythonlibtest-unit-test-tests/lib/python3.10/site-packages/_pytest/config/__init__.py", line 150, in main
    config = _prepareconfig(args, plugins)
  File "/workdir/setuptools-65.6.3/.tox/cpythonlibtest-unit-test-tests/lib/python3.10/site-packages/_pytest/config/__init__.py", line 331, in _prepareconfig
    config = pluginmanager.hook.pytest_cmdline_parse(
  File "/workdir/setuptools-65.6.3/.tox/cpythonlibtest-unit-test-tests/lib/python3.10/site-packages/pluggy/_hooks.py", line 493, in __call__
    return self._hookexec(self.name, self._hookimpls, kwargs, firstresult)
  File "/workdir/setuptools-65.6.3/.tox/cpythonlibtest-unit-test-tests/lib/python3.10/site-packages/pluggy/_manager.py", line 115, in _hookexec
    return self._inner_hookexec(hook_name, methods, kwargs, firstresult)
  File "/workdir/setuptools-65.6.3/.tox/cpythonlibtest-unit-test-tests/lib/python3.10/site-packages/pluggy/_callers.py", line 130, in _multicall
    teardown[0].send(outcome)
  File "/workdir/setuptools-65.6.3/.tox/cpythonlibtest-unit-test-tests/lib/python3.10/site-packages/_pytest/helpconfig.py", line 104, in pytest_cmdline_parse
    config: Config = outcome.get_result()
  File "/workdir/setuptools-65.6.3/.tox/cpythonlibtest-unit-test-tests/lib/python3.10/site-packages/pluggy/_result.py", line 114, in get_result
    raise exc.with_traceback(exc.__traceback__)
  File "/workdir/setuptools-65.6.3/.tox/cpythonlibtest-unit-test-tests/lib/python3.10/site-packages/pluggy/_callers.py", line 77, in _multicall
    res = hook_impl.function(*args)
  File "/workdir/setuptools-65.6.3/.tox/cpythonlibtest-unit-test-tests/lib/python3.10/site-packages/_pytest/config/__init__.py", line 1075, in pytest_cmdline_parse
    self.parse(args)
  File "/workdir/setuptools-65.6.3/.tox/cpythonlibtest-unit-test-tests/lib/python3.10/site-packages/_pytest/config/__init__.py", line 1425, in parse
    self._preparse(args, addopts=addopts)
  File "/workdir/setuptools-65.6.3/.tox/cpythonlibtest-unit-test-tests/lib/python3.10/site-packages/_pytest/config/__init__.py", line 1327, in _preparse
    self.hook.pytest_load_initial_conftests(
  File "/workdir/setuptools-65.6.3/.tox/cpythonlibtest-unit-test-tests/lib/python3.10/site-packages/pluggy/_hooks.py", line 493, in __call__
    return self._hookexec(self.name, self._hookimpls, kwargs, firstresult)
  File "/workdir/setuptools-65.6.3/.tox/cpythonlibtest-unit-test-tests/lib/python3.10/site-packages/pluggy/_manager.py", line 115, in _hookexec
    return self._inner_hookexec(hook_name, methods, kwargs, firstresult)
  File "/workdir/setuptools-65.6.3/.tox/cpythonlibtest-unit-test-tests/lib/python3.10/site-packages/pluggy/_callers.py", line 152, in _multicall
    return outcome.get_result()
  File "/workdir/setuptools-65.6.3/.tox/cpythonlibtest-unit-test-tests/lib/python3.10/site-packages/pluggy/_result.py", line 114, in get_result
    raise exc.with_traceback(exc.__traceback__)
  File "/workdir/setuptools-65.6.3/.tox/cpythonlibtest-unit-test-tests/lib/python3.10/site-packages/pluggy/_callers.py", line 77, in _multicall
    res = hook_impl.function(*args)
  File "/workdir/setuptools-65.6.3/.tox/cpythonlibtest-unit-test-tests/lib/python3.10/site-packages/_pytest/config/__init__.py", line 1153, in pytest_load_initial_conftests
    self.pluginmanager._set_initial_conftests(
  File "/workdir/setuptools-65.6.3/.tox/cpythonlibtest-unit-test-tests/lib/python3.10/site-packages/_pytest/config/__init__.py", line 563, in _set_initial_conftests
    self._try_load_conftest(anchor, importmode, rootpath)
  File "/workdir/setuptools-65.6.3/.tox/cpythonlibtest-unit-test-tests/lib/python3.10/site-packages/_pytest/config/__init__.py", line 580, in _try_load_conftest
    self._getconftestmodules(anchor, importmode, rootpath)
  File "/workdir/setuptools-65.6.3/.tox/cpythonlibtest-unit-test-tests/lib/python3.10/site-packages/_pytest/config/__init__.py", line 609, in _getconftestmodules
    mod = self._importconftest(conftestpath, importmode, rootpath)
  File "/workdir/setuptools-65.6.3/.tox/cpythonlibtest-unit-test-tests/lib/python3.10/site-packages/_pytest/config/__init__.py", line 657, in _importconftest
    self.consider_conftest(mod)
  File "/workdir/setuptools-65.6.3/.tox/cpythonlibtest-unit-test-tests/lib/python3.10/site-packages/_pytest/config/__init__.py", line 739, in consider_conftest
    self.register(conftestmodule, name=conftestmodule.__file__)
  File "/workdir/setuptools-65.6.3/.tox/cpythonlibtest-unit-test-tests/lib/python3.10/site-packages/_pytest/config/__init__.py", line 498, in register
    self.consider_module(plugin)
  File "/workdir/setuptools-65.6.3/.tox/cpythonlibtest-unit-test-tests/lib/python3.10/site-packages/_pytest/config/__init__.py", line 747, in consider_module
    self._import_plugin_specs(getattr(mod, "pytest_plugins", []))
  File "/workdir/setuptools-65.6.3/.tox/cpythonlibtest-unit-test-tests/lib/python3.10/site-packages/_pytest/config/__init__.py", line 754, in _import_plugin_specs
    self.import_plugin(import_spec)
  File "/workdir/setuptools-65.6.3/.tox/cpythonlibtest-unit-test-tests/lib/python3.10/site-packages/_pytest/config/__init__.py", line 783, in import_plugin
    raise ImportError(
  File "/workdir/setuptools-65.6.3/.tox/cpythonlibtest-unit-test-tests/lib/python3.10/site-packages/_pytest/config/__init__.py", line 781, in import_plugin
    __import__(importspec)
ImportError: Error importing plugin "setuptools.tests.fixtures": No module named 'setuptools.tests'
ERROR: InvocationError for command /workdir/setuptools-65.6.3/.tox/cpythonlibtest-unit-test-tests/bin/pytest -v --tb=native --junitxml /workdir/results/setuptools/65.6.3/1/cpython-test-results.xml (exited with code 1)
___________________________________ summary ____________________________________
ERROR:   cpythonlibtest-unit-test-tests: commands failed
