.package create: /workdir/mkdocs-1.4.2/.tox/.package
.package installdeps: hatchling
cpythonlibtest-unit-test-tests create: /workdir/mkdocs-1.4.2/.tox/cpythonlibtest-unit-test-tests
cpythonlibtest-unit-test-tests installdeps: mock, pytest
cpythonlibtest-unit-test-tests inst: /workdir/mkdocs-1.4.2/.tox/.tmp/package/1/mkdocs-1.4.2.tar.gz
cpythonlibtest-unit-test-tests installed: click==8.1.7,exceptiongroup==1.2.0,ghp-import==2.1.0,iniconfig==2.0.0,Jinja2==3.1.2,Markdown==3.3.7,MarkupSafe==2.1.3,mergedeep==1.3.4,mkdocs @ file:///workdir/mkdocs-1.4.2/.tox/.tmp/package/1/mkdocs-1.4.2.tar.gz#sha256=7f8bde433fde500657c06e9258ecd627a4ae77c93277993e421dce2a84acdec4,mock==5.1.0,packaging==23.2,pluggy==1.3.0,pytest==7.4.3,python-dateutil==2.8.2,PyYAML==6.0.1,pyyaml_env_tag==0.1,six==1.16.0,tomli==2.0.1,watchdog==3.0.0
cpythonlibtest-unit-test-tests run-test-pre: PYTHONHASHSEED='3454410143'
cpythonlibtest-unit-test-tests run-test: commands[0] | pytest -v --tb=native --junitxml /workdir/results/mkdocs/1.4.2/1/cpython-test-results.xml
============================= test session starts ==============================
platform linux -- Python 3.10.8, pytest-7.4.3, pluggy-1.3.0 -- /workdir/mkdocs-1.4.2/.tox/cpythonlibtest-unit-test-tests/bin/python
cachedir: .tox/cpythonlibtest-unit-test-tests/.pytest_cache
rootdir: /workdir/mkdocs-1.4.2
collecting ... collected 0 items

- generated xml file: /workdir/results/mkdocs/1.4.2/1/cpython-test-results.xml -
============================ no tests ran in 0.24s =============================
ERROR: InvocationError for command /workdir/mkdocs-1.4.2/.tox/cpythonlibtest-unit-test-tests/bin/pytest -v --tb=native --junitxml /workdir/results/mkdocs/1.4.2/1/cpython-test-results.xml (exited with code 5)
___________________________________ summary ____________________________________
ERROR:   cpythonlibtest-unit-test-tests: commands failed
